Workbook

Sheet Dashboard
B1: PERSONAL LIFE TRACKER 2026
B2: Your daily companion for habits, health, and wealth • Tap to check, red = pending, green = done!
B4: =TODAY()
B6: CURRENT YEAR PERFORMANCE — KEY METRICS
B7: 🕌 SALAT | D7: 💪 GYM | F7: 💊 SUPPLEMENTS | H7: 👟 STEPS
B8: =IFERROR(COUNTIF('Salat Tracker'!I$4:I$368,1)/COUNTA('Salat Tracker'!A$4:A$368),0) | D8: =IFERROR(COUNTIFS('Gym Routine'!C$4:C$368,"Grind Day",'Gym Routine'!D$4:D$368,1)/COUNTIF('Gym Routine'!C$4:C$368,"Grind Day"),0) | F8: =IFERROR(COUNTIF('Supplements'!E$4:E$368,1)/COUNTA('Supplements'!A$4:A$368),0) | H8: =IFERROR(COUNTIF('Steps Tracker'!E$4:E$368,1)/COUNTA('Steps Tracker'!A$4:A$368),0)
B9: Prayers 100% | D9: Workouts Done | F9: Both Taken | H9: Goal Met Days
B11: 🏃 RUNNING | D11: 💰 INCOME YTD | F11: 📉 EXPENSE YTD | H11: 📈 SAVINGS YTD
B12: =IFERROR(SUM('Running Tracker'!D$4:D$368),0) | D12: =IFERROR(SUM('Expense & Savings'!E$4:E$368),0) | F12: =IFERROR(SUM('Expense & Savings'!F$4:F$368),0) | H12: =IFERROR(SUM('Expense & Savings'!E$4:E$368)-SUM('Expense & Savings'!F$4:F$368),0)
B13: Total KM Run | D13: All Income | F13: All Expenses | H13: Net Savings
B15: OVERALL LIFE SCORE 2026
B16: ='Monthly Summary'!K16
B18: Salat 25% + Gym 20% + Supplements 15% + Steps 15% + Running 10% + Savings 15%
B20: MONTHLY PERFORMANCE AT A GLANCE
B21: Month | C21: Salat % | D21: Gym % | E21: Suppl.% | F21: Steps % | G21: Running KM | H21: Overall
B22: January | C22: ='Monthly Summary'!B4 | D22: ='Monthly Summary'!C4 | E22: ='Monthly Summary'!D4 | F22: ='Monthly Summary'!E4 | G22: ='Monthly Summary'!F4 | H22: ='Monthly Summary'!K4
B23: February | C23: ='Monthly Summary'!B5 | D23: ='Monthly Summary'!C5 | E23: ='Monthly Summary'!D5 | F23: ='Monthly Summary'!E5 | G23: ='Monthly Summary'!F5 | H23: ='Monthly Summary'!K5
B24: March | C24: ='Monthly Summary'!B6 | D24: ='Monthly Summary'!C6 | E24: ='Monthly Summary'!D6 | F24: ='Monthly Summary'!E6 | G24: ='Monthly Summary'!F6 | H24: ='Monthly Summary'!K6
B25: April | C25: ='Monthly Summary'!B7 | D25: ='Monthly Summary'!C7 | E25: ='Monthly Summary'!D7 | F25: ='Monthly Summary'!E7 | G25: ='Monthly Summary'!F7 | H25: ='Monthly Summary'!K7
B26: May | C26: ='Monthly Summary'!B8 | D26: ='Monthly Summary'!C8 | E26: ='Monthly Summary'!D8 | F26: ='Monthly Summary'!E8 | G26: ='Monthly Summary'!F8 | H26: ='Monthly Summary'!K8
B27: June | C27: ='Monthly Summary'!B9 | D27: ='Monthly Summary'!C9 | E27: ='Monthly Summary'!D9 | F27: ='Monthly Summary'!E9 | G27: ='Monthly Summary'!F9 | H27: ='Monthly Summary'!K9
B28: July | C28: ='Monthly Summary'!B10 | D28: ='Monthly Summary'!C10 | E28: ='Monthly Summary'!D10 | F28: ='Monthly Summary'!E10 | G28: ='Monthly Summary'!F10 | H28: ='Monthly Summary'!K10
B29: August | C29: ='Monthly Summary'!B11 | D29: ='Monthly Summary'!C11 | E29: ='Monthly Summary'!D11 | F29: ='Monthly Summary'!E11 | G29: ='Monthly Summary'!F11 | H29: ='Monthly Summary'!K11
B30: September | C30: ='Monthly Summary'!B12 | D30: ='Monthly Summary'!C12 | E30: ='Monthly Summary'!D12 | F30: ='Monthly Summary'!E12 | G30: ='Monthly Summary'!F12 | H30: ='Monthly Summary'!K12
B31: October | C31: ='Monthly Summary'!B13 | D31: ='Monthly Summary'!C13 | E31: ='Monthly Summary'!D13 | F31: ='Monthly Summary'!E13 | G31: ='Monthly Summary'!F13 | H31: ='Monthly Summary'!K13
B32: November | C32: ='Monthly Summary'!B14 | D32: ='Monthly Summary'!C14 | E32: ='Monthly Summary'!D14 | F32: ='Monthly Summary'!E14 | G32: ='Monthly Summary'!F14 | H32: ='Monthly Summary'!K14
B33: December | C33: ='Monthly Summary'!B15 | D33: ='Monthly Summary'!C15 | E33: ='Monthly Summary'!D15 | F33: ='Monthly Summary'!E15 | G33: ='Monthly Summary'!F15 | H33: ='Monthly Summary'!K15

Sheet Salat Tracker
A1: 🌙 SALAT TRACKER 2026
A2: Tap a prayer cell to check ✓ (green) or uncheck (red) • All cells start RED — go green as you pray!
A3: Date | B3: Day | C3: Fajr | D3: Dhuhr | E3: Asr | F3: Maghrib | G3: Isha | H3: Total Prayers | I3: Completion % | J3: Notes
A4: 46023 | B4: Thursday | C4: 0 | D4: 0 | E4: 0 | F4: 0 | G4: 0 | H4: =COUNTIF(C4:G4,1) | I4: =H4/5
A5: 46024 | B5: Friday | C5: 0 | D5: 0 | E5: 0 | F5: 0 | G5: 0 | H5: =COUNTIF(C5:G5,1) | I5: =H5/5
A6: 46025 | B6: Saturday | C6: 0 | D6: 0 | E6: 0 | F6: 0 | G6: 0 | H6: =COUNTIF(C6:G6,1) | I6: =H6/5
A7: 46026 | B7: Sunday | C7: 0 | D7: 0 | E7: 0 | F7: 0 | G7: 0 | H7: =COUNTIF(C7:G7,1) | I7: =H7/5
A8: 46027 | B8: Monday | C8: 0 | D8: 0 | E8: 0 | F8: 0 | G8: 0 | H8: =COUNTIF(C8:G8,1) | I8: =H8/5
A9: 46028 | B9: Tuesday | C9: 0 | D9: 0 | E9: 0 | F9: 0 | G9: 0 | H9: =COUNTIF(C9:G9,1) | I9: =H9/5
A10: 46029 | B10: Wednesday | C10: 0 | D10: 0 | E10: 0 | F10: 0 | G10: 0 | H10: =COUNTIF(C10:G10,1) | I10: =H10/5
A11: 46030 | B11: Thursday | C11: 0 | D11: 0 | E11: 0 | F11: 0 | G11: 0 | H11: =COUNTIF(C11:G11,1) | I11: =H11/5
A12: 46031 | B12: Friday | C12: 0 | D12: 0 | E12: 0 | F12: 0 | G12: 0 | H12: =COUNTIF(C12:G12,1) | I12: =H12/5
A13: 46032 | B13: Saturday | C13: 0 | D13: 0 | E13: 0 | F13: 0 | G13: 0 | H13: =COUNTIF(C13:G13,1) | I13: =H13/5
A14: 46033 | B14: Sunday | C14: 0 | D14: 0 | E14: 0 | F14: 0 | G14: 0 | H14: =COUNTIF(C14:G14,1) | I14: =H14/5
A15: 46034 | B15: Monday | C15: 0 | D15: 0 | E15: 0 | F15: 0 | G15: 0 | H15: =COUNTIF(C15:G15,1) | I15: =H15/5
... A368: 46387 | B368: Thursday | C368: 0 | D368: 0 | E368: 0 | F368: 0 | G368: 0 | H368: =COUNTIF(C368:G368,1) | I368: =H368/5

Sheet Gym Routine
A1: 💪 GYM ROUTINE TRACKER 2026
A2: Mon/Tue/Wed/Fri/Sat = Grind Day • Thu/Sun = Rest Day • Tap Workout Done to check green — past missed Grind Days stay RED
A3: Date | B3: Day | C3: Planned Type | D3: Workout Done | E3: Workout Name | F3: Body Part | G3: Duration (min) | H3: Intensity | I3: Notes
A4: 46023 | B4: Thursday | C4: Rest Day | D4: 0
A5: 46024 | B5: Friday | C5: Grind Day | D5: 0
A6: 46025 | B6: Saturday | C6: Grind Day | D6: 0
A7: 46026 | B7: Sunday | C7: Rest Day | D7: 0
A8: 46027 | B8: Monday | C8: Grind Day | D8: 0
A9: 46028 | B9: Tuesday | C9: Grind Day | D9: 0
A10: 46029 | B10: Wednesday | C10: Grind Day | D10: 0
A11: 46030 | B11: Thursday | C11: Rest Day | D11: 0
A12: 46031 | B12: Friday | C12: Grind Day | D12: 0
A13: 46032 | B13: Saturday | C13: Grind Day | D13: 0
A14: 46033 | B14: Sunday | C14: Rest Day | D14: 0
A15: 46034 | B15: Monday | C15: Grind Day | D15: 0
... A368: 46387 | B368: Thursday | C368: Rest Day | D368: 0

Sheet Supplements
A1: 💊 SUPPLEMENTS TRACKER 2026
A2: Tap each cell to check • Both Completed auto-calculates • Unchecked cells → RED by default
A3: Date | B3: Day | C3: Multivitamin | D3: Omega | E3: Both Completed | F3: Notes
A4: 46023 | B4: Thursday | C4: 0 | D4: 0 | E4: =C4*D4
A5: 46024 | B5: Friday | C5: 0 | D5: 0 | E5: =C5*D5
A6: 46025 | B6: Saturday | C6: 0 | D6: 0 | E6: =C6*D6
A7: 46026 | B7: Sunday | C7: 0 | D7: 0 | E7: =C7*D7
A8: 46027 | B8: Monday | C8: 0 | D8: 0 | E8: =C8*D8
A9: 46028 | B9: Tuesday | C9: 0 | D9: 0 | E9: =C9*D9
A10: 46029 | B10: Wednesday | C10: 0 | D10: 0 | E10: =C10*D10
A11: 46030 | B11: Thursday | C11: 0 | D11: 0 | E11: =C11*D11
A12: 46031 | B12: Friday | C12: 0 | D12: 0 | E12: =C12*D12
A13: 46032 | B13: Saturday | C13: 0 | D13: 0 | E13: =C13*D13
A14: 46033 | B14: Sunday | C14: 0 | D14: 0 | E14: =C14*D14
A15: 46034 | B15: Monday | C15: 0 | D15: 0 | E15: =C15*D15
... A368: 46387 | B368: Thursday | C368: 0 | D368: 0 | E368: =C368*D368

Sheet Steps Tracker
A1: 👟 STEPS TRACKER 2026
A2: Enter your step count — Goal Met turns GREEN automatically when steps ≥ goal, RED when below
A3: Date | B3: Day | C3: Steps | D3: Goal | E3: Goal Met | F3: Difference | G3: Notes
A4: 46023 | B4: Thursday | D4: ='Goals & Settings'!B5 | E4: =IF(C4="","",IF(C4>=D4,1,0)) | F4: =IF(C4="","",C4-D4)
A5: 46024 | B5: Friday | D5: ='Goals & Settings'!B5 | E5: =IF(C5="","",IF(C5>=D5,1,0)) | F5: =IF(C5="","",C5-D5)
A6: 46025 | B6: Saturday | D6: ='Goals & Settings'!B5 | E6: =IF(C6="","",IF(C6>=D6,1,0)) | F6: =IF(C6="","",C6-D6)
A7: 46026 | B7: Sunday | D7: ='Goals & Settings'!B5 | E7: =IF(C7="","",IF(C7>=D7,1,0)) | F7: =IF(C7="","",C7-D7)
A8: 46027 | B8: Monday | D8: ='Goals & Settings'!B5 | E8: =IF(C8="","",IF(C8>=D8,1,0)) | F8: =IF(C8="","",C8-D8)
A9: 46028 | B9: Tuesday | D9: ='Goals & Settings'!B5 | E9: =IF(C9="","",IF(C9>=D9,1,0)) | F9: =IF(C9="","",C9-D9)
A10: 46029 | B10: Wednesday | D10: ='Goals & Settings'!B5 | E10: =IF(C10="","",IF(C10>=D10,1,0)) | F10: =IF(C10="","",C10-D10)
A11: 46030 | B11: Thursday | D11: ='Goals & Settings'!B5 | E11: =IF(C11="","",IF(C11>=D11,1,0)) | F11: =IF(C11="","",C11-D11)
A12: 46031 | B12: Friday | D12: ='Goals & Settings'!B5 | E12: =IF(C12="","",IF(C12>=D12,1,0)) | F12: =IF(C12="","",C12-D12)
A13: 46032 | B13: Saturday | D13: ='Goals & Settings'!B5 | E13: =IF(C13="","",IF(C13>=D13,1,0)) | F13: =IF(C13="","",C13-D13)
A14: 46033 | B14: Sunday | D14: ='Goals & Settings'!B5 | E14: =IF(C14="","",IF(C14>=D14,1,0)) | F14: =IF(C14="","",C14-D14)
A15: 46034 | B15: Monday | D15: ='Goals & Settings'!B5 | E15: =IF(C15="","",IF(C15>=D15,1,0)) | F15: =IF(C15="","",C15-D15)
A16: 46035 | B16: Tuesday | D16: ='Goals & Settings'!B5 | E16: =IF(C16="","",IF(C16>=D16,1,0)) | F16: =IF(C16="","",C16-D16)
A17: 46036 | B17: Wednesday | D17: ='Goals & Settings'!B5 | E17: =IF(C17="","",IF(C17>=D17,1,0)) | F17: =IF(C17="","",C17-D17)
A18: 46037 | B18: Thursday | D18: ='Goals & Settings'!B5 | E18: =IF(C18="","",IF(C18>=D18,1,0)) | F18: =IF(C18="","",C18-D18)
A19: 46038 | B19: Friday | D19: ='Goals & Settings'!B5 | E19: =IF(C19="","",IF(C19>=D19,1,0)) | F19: =IF(C19="","",C19-D19)
A20: 46039 | B20: Saturday | D20: ='Goals & Settings'!B5 | E20: =IF(C20="","",IF(C20>=D20,1,0)) | F20: =IF(C20="","",C20-D20)
A21: 46040 | B21: Sunday | D21: ='Goals & Settings'!B5 | E21: =IF(C21="","",IF(C21>=D21,1,0)) | F21: =IF(C21="","",C21-D21)
A22: 46041 | B22: Monday | D22: ='Goals & Settings'!B5 | E22: =IF(C22="","",IF(C22>=D22,1,0)) | F22: =IF(C22="","",C22-D22)
A23: 46042 | B23: Tuesday | D23: ='Goals & Settings'!B5 | E23: =IF(C23="","",IF(C23>=D23,1,0)) | F23: =IF(C23="","",C23-D23)
A24: 46043 | B24: Wednesday | D24: ='Goals & Settings'!B5 | E24: =IF(C24="","",IF(C24>=D24,1,0)) | F24: =IF(C24="","",C24-D24)
A25: 46044 | B25: Thursday | D25: ='Goals & Settings'!B5 | E25: =IF(C25="","",IF(C25>=D25,1,0)) | F25: =IF(C25="","",C25-D25)
A26: 46045 | B26: Friday | D26: ='Goals & Settings'!B5 | E26: =IF(C26="","",IF(C26>=D26,1,0)) | F26: =IF(C26="","",C26-D26)
A27: 46046 | B27: Saturday | D27: ='Goals & Settings'!B5 | E27: =IF(C27="","",IF(C27>=D27,1,0)) | F27: =IF(C27="","",C27-D27)
A28: 46047 | B28: Sunday | D28: ='Goals & Settings'!B5 | E28: =IF(C28="","",IF(C28>=D28,1,0)) | F28: =IF(C28="","",C28-D28)
A29: 46048 | B29: Monday | D29: ='Goals & Settings'!B5 | E29: =IF(C29="","",IF(C29>=D29,1,0)) | F29: =IF(C29="","",C29-D29)
A30: 46049 | B30: Tuesday | D30: ='Goals & Settings'!B5 | E30: =IF(C30="","",IF(C30>=D30,1,0)) | F30: =IF(C30="","",C30-D30)
A31: 46050 | B31: Wednesday | D31: ='Goals & Settings'!B5 | E31: =IF(C31="","",IF(C31>=D31,1,0)) | F31: =IF(C31="","",C31-D31)
A32: 46051 | B32: Thursday | D32: ='Goals & Settings'!B5 | E32: =IF(C32="","",IF(C32>=D32,1,0)) | F32: =IF(C32="","",C32-D32)
A33: 46052 | B33: Friday | D33: ='Goals & Settings'!B5 | E33: =IF(C33="","",IF(C33>=D33,1,0)) | F33: =IF(C33="","",C33-D33)
A34: 46053 | B34: Saturday | D34: ='Goals & Settings'!B5 | E34: =IF(C34="","",IF(C34>=D34,1,0)) | F34: =IF(C34="","",C34-D34)
A35: 46054 | B35: Sunday | D35: ='Goals & Settings'!B5 | E35: =IF(C35="","",IF(C35>=D35,1,0)) | F35: =IF(C35="","",C35-D35)
A36: 46055 | B36: Monday | D36: ='Goals & Settings'!B5 | E36: =IF(C36="","",IF(C36>=D36,1,0)) | F36: =IF(C36="","",C36-D36)
A37: 46056 | B37: Tuesday | D37: ='Goals & Settings'!B5 | E37: =IF(C37="","",IF(C37>=D37,1,0)) | F37: =IF(C37="","",C37-D37)
A38: 46057 | B38: Wednesday | D38: ='Goals & Settings'!B5 | E38: =IF(C38="","",IF(C38>=D38,1,0)) | F38: =IF(C38="","",C38-D38)
A39: 46058 | B39: Thursday | D39: ='Goals & Settings'!B5 | E39: =IF(C39="","",IF(C39>=D39,1,0)) | F39: =IF(C39="","",C39-D39)
A40: 46059 | B40: Friday | D40: ='Goals & Settings'!B5 | E40: =IF(C40="","",IF(C40>=D40,1,0)) | F40: =IF(C40="","",C40-D40)
...

Sheet Running Tracker
A1: 🏃 RUNNING TRACKER 2026
A2: Tap 'Ran Today' to check • Pace auto-calculates • Rest days stay neutral (orange reminder only)
A3: Date | B3: Day | C3: Ran Today | D3: Distance (KM) | E3: Duration (min) | F3: Pace (min/km) | G3: Calories | H3: Route / Location | I3: Notes
A4: 46023 | B4: Thursday | C4: 0 | F4: =IFERROR(IF(AND(D4<>"",E4<>""),E4/D4,""),"")
A5: 46024 | B5: Friday | C5: 0 | F5: =IFERROR(IF(AND(D5<>"",E5<>""),E5/D5,""),"")
A6: 46025 | B6: Saturday | C6: 0 | F6: =IFERROR(IF(AND(D6<>"",E6<>""),E6/D6,""),"")
A7: 46026 | B7: Sunday | C7: 0 | F7: =IFERROR(IF(AND(D7<>"",E7<>""),E7/D7,""),"")
A8: 46027 | B8: Monday | C8: 0 | F8: =IFERROR(IF(AND(D8<>"",E8<>""),E8/D8,""),"")
A9: 46028 | B9: Tuesday | C9: 0 | F9: =IFERROR(IF(AND(D9<>"",E9<>""),E9/D9,""),"")
A10: 46029 | B10: Wednesday | C10: 0 | F10: =IFERROR(IF(AND(D10<>"",E10<>""),E10/D10,""),"")
A11: 46030 | B11: Thursday | C11: 0 | F11: =IFERROR(IF(AND(D11<>"",E11<>""),E11/D11,""),"")
A12: 46031 | B12: Friday | C12: 0 | F12: =IFERROR(IF(AND(D12<>"",E12<>""),E12/D12,""),"")
A13: 46032 | B13: Saturday | C13: 0 | F13: =IFERROR(IF(AND(D13<>"",E13<>""),E13/D13,""),"")
A14: 46033 | B14: Sunday | C14: 0 | F14: =IFERROR(IF(AND(D14<>"",E14<>""),E14/D14,""),"")
A15: 46034 | B15: Monday | C15: 0 | F15: =IFERROR(IF(AND(D15<>"",E15<>""),E15/D15,""),"")
... A368: 46387 | B368: Thursday | C368: 0 | F368: =IFERROR(IF(AND(D368<>"",E368<>""),E368/D368,""),"")

Sheet Expense & Savings
A1: 💰 EXPENSE & SAVINGS TRACKER 2026
A2: Track income, expenses, and savings daily • Savings = Income − Expense
A3: Date | B3: Day | C3: Category | D3: Description | E3: Income | F3: Expense | G3: Savings | H3: Payment Method | I3: Notes
A4: 46023 | B4: Thursday | G4: =IFERROR(IF(AND(E4<>"",F4<>""),E4-F4,IF(E4<>"",E4,IF(F4<>"",-F4,""))),"")
A5: 46024 | B5: Friday | G5: =IFERROR(IF(AND(E5<>"",F5<>""),E5-F5,IF(E5<>"",E5,IF(F5<>"",-F5,""))),"")
A6: 46025 | B6: Saturday | G6: =IFERROR(IF(AND(E6<>"",F6<>""),E6-F6,IF(E6<>"",E6,IF(F6<>"",-F6,""))),"")
A7: 46026 | B7: Sunday | G7: =IFERROR(IF(AND(E7<>"",F7<>""),E7-F7,IF(E7<>"",E7,IF(F7<>"",-F7,""))),"")
A8: 46027 | B8: Monday | G8: =IFERROR(IF(AND(E8<>"",F8<>""),E8-F8,IF(E8<>"",E8,IF(F8<>"",-F8,""))),"")
A9: 46028 | B9: Tuesday | G9: =IFERROR(IF(AND(E9<>"",F9<>""),E9-F9,IF(E9<>"",E9,IF(F9<>"",-F9,""))),"")
A10: 46029 | B10: Wednesday | G10: =IFERROR(IF(AND(E10<>"",F10<>""),E10-F10,IF(E10<>"",E10,IF(F10<>"",-F10,""))),"")
A11: 46030 | B11: Thursday | G11: =IFERROR(IF(AND(E11<>"",F11<>""),E11-F11,IF(E11<>"",E11,IF(F11<>"",-F11,""))),"")
A12: 46031 | B12: Friday | G12: =IFERROR(IF(AND(E12<>"",F12<>""),E12-F12,IF(E12<>"",E12,IF(F12<>"",-F12,""))),"")
A13: 46032 | B13: Saturday | G13: =IFERROR(IF(AND(E13<>"",F13<>""),E13-F13,IF(E13<>"",E13,IF(F13<>"",-F13,""))),"")
A14: 46033 | B14: Sunday | G14: =IFERROR(IF(AND(E14<>"",F14<>""),E14-F14,IF(E14<>"",E14,IF(F14<>"",-F14,""))),"")
A15: 46034 | B15: Monday | G15: =IFERROR(IF(AND(E15<>"",F15<>""),E15-F15,IF(E15<>"",E15,IF(F15<>"",-F15,""))),"")
... A368: 46387 | B368: Thursday | G368: =IFERROR(IF(AND(E368<>"",F368<>""),E368-F368,IF(E368<>"",E368,IF(F368<>"",-F368,""))),"")

Sheet Goals & Settings
A1: ⚙️ GOALS & SETTINGS
A2: Edit the yellow value cells below • All tracker sheets reference these automatically
A3: DAILY HABIT GOALS
A4: Setting | B4: Value | C4: Unit | D4: Notes
A5: Daily Steps Goal | B5: 10000 | C5: steps/day | D5: Steps Tracker references this cell
A6: Daily Salat Goal | B6: 5 | C6: prayers/day | D6: Max 5 prayers
A7: Daily Supplements Goal | B7: 2 | C7: supplements/day | D7: Multivitamin + Omega = 2
A8: Weekly Gym Grind Days Goal | B8: 5 | C8: days/week | D8: Mon Tue Wed Fri Sat = 5 Grind Days
A9: MONTHLY GOALS (EDITABLE)
A10: Setting | B10: Value | C10: Unit | D10: Notes
A11: Monthly Running KM Goal | B11: 0 | C11: km/month | D11: Set your monthly running target
A12: Monthly Savings Goal | B12: 0 | C12: currency | D12: Set your monthly savings target
A13: TRACKER DATE RANGE
A14: Start Date | B14: 46023 | C14: DD-MMM-YYYY | D14: First tracked date
A15: End Date | B15: 46387 | C15: DD-MMM-YYYY | D15: Last tracked date

Sheet Monthly Summary
A1: 📊 MONTHLY SUMMARY 2026
A2: Overall Score = Salat 25% + Gym 20% + Supplements 15% + Steps 15% + Running 10% + Savings 15%
A3: Month | B3: Salat % | C3: Gym % | D3: Suppl. % | E3: Steps Goal % | F3: Running KM | G3: Total Income | H3: Total Expense | I3: Total Savings | J3: Savings Rate % | K3: Overall Score %
A4: January | B4: =IFERROR(AVERAGE('Salat Tracker'!I4:I34),0) | C4: =IFERROR(COUNTIFS('Gym Routine'!C4:C34,"Grind Day",'Gym Routine'!D4:D34,1)/22,0) | D4: =IFERROR(COUNTIF('Supplements'!E4:E34,1)/31,0) | E4: =IFERROR(COUNTIF('Steps Tracker'!E4:E34,1)/31,0) | F4: =IFERROR(SUMIF('Running Tracker'!C4:C34,1,'Running Tracker'!D4:D34),0) | G4: =IFERROR(SUM('Expense & Savings'!E4:E34),0) | H4: =IFERROR(SUM('Expense & Savings'!F4:F34),0) | I4: =IFERROR(G4-H4,0) | J4: =IFERROR(I4/G4,0) | K4: =B4*0.25+C4*0.20+D4*0.15+E4*0.15+MIN(IFERROR(F4/'Goals & Settings'!B11,0),1)*0.10+MIN(IFERROR(I4/'Goals & Settings'!B12,0),1)*0.15
A5: February | B5: =IFERROR(AVERAGE('Salat Tracker'!I35:I62),0) | C5: =IFERROR(COUNTIFS('Gym Routine'!C35:C62,"Grind Day",'Gym Routine'!D35:D62,1)/20,0) | D5: =IFERROR(COUNTIF('Supplements'!E35:E62,1)/28,0) | E5: =IFERROR(COUNTIF('Steps Tracker'!E35:E62,1)/28,0) | F5: =IFERROR(SUMIF('Running Tracker'!C35:C62,1,'Running Tracker'!D35:D62),0) | G5: =IFERROR(SUM('Expense & Savings'!E35:E62),0) | H5: =IFERROR(SUM('Expense & Savings'!F35:F62),0) | I5: =IFERROR(G5-H5,0) | J5: =IFERROR(I5/G5,0) | K5: =B5*0.25+C5*0.20+D5*0.15+E5*0.15+MIN(IFERROR(F5/'Goals & Settings'!B11,0),1)*0.10+MIN(IFERROR(I5/'Goals & Settings'!B12,0),1)*0.15
A6: March | B6: =IFERROR(AVERAGE('Salat Tracker'!I63:I93),0) | C6: =IFERROR(COUNTIFS('Gym Routine'!C63:C93,"Grind Day",'Gym Routine'!D63:D93,1)/22,0) | D6: =IFERROR(COUNTIF('Supplements'!E63:E93,1)/31,0) | E6: =IFERROR(COUNTIF('Steps Tracker'!E63:E93,1)/31,0) | F6: =IFERROR(SUMIF('Running Tracker'!C63:C93,1,'Running Tracker'!D63:D93),0) | G6: =IFERROR(SUM('Expense & Savings'!E63:E93),0) | H6: =IFERROR(SUM('Expense & Savings'!F63:F93),0) | I6: =IFERROR(G6-H6,0) | J6: =IFERROR(I6/G6,0) | K6: =B6*0.25+C6*0.20+D6*0.15+E6*0.15+MIN(IFERROR(F6/'Goals & Settings'!B11,0),1)*0.10+MIN(IFERROR(I6/'Goals & Settings'!B12,0),1)*0.15
A7: April | B7: =IFERROR(AVERAGE('Salat Tracker'!I94:I123),0) | C7: =IFERROR(COUNTIFS('Gym Routine'!C94:C123,"Grind Day",'Gym Routine'!D94:D123,1)/21,0) | D7: =IFERROR(COUNTIF('Supplements'!E94:E123,1)/30,0) | E7: =IFERROR(COUNTIF('Steps Tracker'!E94:E123,1)/30,0) | F7: =IFERROR(SUMIF('Running Tracker'!C94:C123,1,'Running Tracker'!D94:D123),0) | G7: =IFERROR(SUM('Expense & Savings'!E94:E123),0) | H7: =IFERROR(SUM('Expense & Savings'!F94:F123),0) | I7: =IFERROR(G7-H7,0) | J7: =IFERROR(I7/G7,0) | K7: =B7*0.25+C7*0.20+D7*0.15+E7*0.15+MIN(IFERROR(F7/'Goals & Settings'!B11,0),1)*0.10+MIN(IFERROR(I7/'Goals & Settings'!B12,0),1)*0.15
A8: May | B8: =IFERROR(AVERAGE('Salat Tracker'!I124:I154),0) | C8: =IFERROR(COUNTIFS('Gym Routine'!C124:C154,"Grind Day",'Gym Routine'!D124:D154,1)/22,0) | D8: =IFERROR(COUNTIF('Supplements'!E124:E154,1)/31,0) | E8: =IFERROR(COUNTIF('Steps Tracker'!E124:E154,1)/31,0) | F8: =IFERROR(SUMIF('Running Tracker'!C124:C154,1,'Running Tracker'!D124:D154),0) | G8: =IFERROR(SUM('Expense & Savings'!E124:E154),0) | H8: =IFERROR(SUM('Expense & Savings'!F124:F154),0) | I8: =IFERROR(G8-H8,0) | J8: =IFERROR(I8/G8,0) | K8: =B8*0.25+C8*0.20+D8*0.15+E8*0.15+MIN(IFERROR(F8/'Goals & Settings'!B11,0),1)*0.10+MIN(IFERROR(I8/'Goals & Settings'!B12,0),1)*0.15
A9: June | B9: =IFERROR(AVERAGE('Salat Tracker'!I155:I184),0) | C9: =IFERROR(COUNTIFS('Gym Routine'!C155:C184,"Grind Day",'Gym Routine'!D155:D184,1)/22,0) | D9: =IFERROR(COUNTIF('Supplements'!E155:E184,1)/30,0) | E9: =IFERROR(COUNTIF('Steps Tracker'!E155:E184,1)/30,0) | F9: =IFERROR(SUMIF('Running Tracker'!C155:C184,1,'Running Tracker'!D155:D184),0) | G9: =IFERROR(SUM('Expense & Savings'!E155:E184),0) | H9: =IFERROR(SUM('Expense & Savings'!F155:F184),0) | I9: =IFERROR(G9-H9,0) | J9: =IFERROR(I9/G9,0) | K9: =B9*0.25+C9*0.20+D9*0.15+E9*0.15+MIN(IFERROR(F9/'Goals & Settings'!B11,0),1)*0.10+MIN(IFERROR(I9/'Goals & Settings'!B12,0),1)*0.15
A10: July | B10: =IFERROR(AVERAGE('Salat Tracker'!I185:I215),0) | C10: =IFERROR(COUNTIFS('Gym Routine'!C185:C215,"Grind Day",'Gym Routine'!D185:D215,1)/22,0) | D10: =IFERROR(COUNTIF('Supplements'!E185:E215,1)/31,0) | E10: =IFERROR(COUNTIF('Steps Tracker'!E185:E215,1)/31,0) | F10: =IFERROR(SUMIF('Running Tracker'!C185:C215,1,'Running Tracker'!D185:D215),0) | G10: =IFERROR(SUM('Expense & Savings'!E185:E215),0) | H10: =IFERROR(SUM('Expense & Savings'!F185:F215),0) | I10: =IFERROR(G10-H10,0) | J10: =IFERROR(I10/G10,0) | K10: =B10*0.25+C10*0.20+D10*0.15+E10*0.15+MIN(IFERROR(F10/'Goals & Settings'!B11,0),1)*0.10+MIN(IFERROR(I10/'Goals & Settings'!B12,0),1)*0.15
A11: August | B11: =IFERROR(AVERAGE('Salat Tracker'!I216:I246),0) | C11: =IFERROR(COUNTIFS('Gym Routine'!C216:C246,"Grind Day",'Gym Routine'!D216:D246,1)/22,0) | D11: =IFERROR(COUNTIF('Supplements'!E216:E246,1)/31,0) | E11: =IFERROR(COUNTIF('Steps Tracker'!E216:E246,1)/31,0) | F11: =IFERROR(SUMIF('Running Tracker'!C216:C246,1,'Running Tracker'!D216:D246),0) | G11: =IFERROR(SUM('Expense & Savings'!E216:E246),0) | H11: =IFERROR(SUM('Expense & Savings'!F216:F246),0) | I11: =IFERROR(G11-H11,0) | J11: =IFERROR(I11/G11,0) | K11: =B11*0.25+C11*0.20+D11*0.15+E11*0.15+MIN(IFERROR(F11/'Goals & Settings'!B11,0),1)*0.10+MIN(IFERROR(I11/'Goals & Settings'!B12,0),1)*0.15
A12: September | B12: =IFERROR(AVERAGE('Salat Tracker'!I247:I276),0) | C12: =IFERROR(COUNTIFS('Gym Routine'!C247:C276,"Grind Day",'Gym Routine'!D247:D276,1)/22,0) | D12: =IFERROR(COUNTIF('Supplements'!E247:E276,1)/30,0) | E12: =IFERROR(COUNTIF('Steps Tracker'!E247:E276,1)/30,0) | F12: =IFERROR(SUMIF('Running Tracker'!C247:C276,1,'Running Tracker'!D247:D276),0) | G12: =IFERROR(SUM('Expense & Savings'!E247:E276),0) | H12: =IFERROR(SUM('Expense & Savings'!F247:F276),0) | I12: =IFERROR(G12-H12,0) | J12: =IFERROR(I12/G12,0) | K12: =B12*0.25+C12*0.20+D12*0.15+E12*0.15+MIN(IFERROR(F12/'Goals & Settings'!B11,0),1)*0.10+MIN(IFERROR(I12/'Goals & Settings'!B12,0),1)*0.15
A13: October | B13: =IFERROR(AVERAGE('Salat Tracker'!I277:I307),0) | C13: =IFERROR(COUNTIFS('Gym Routine'!C277:C307,"Grind Day",'Gym Routine'!D277:D307,1)/22,0) | D13: =IFERROR(COUNTIF('Supplements'!E277:E307,1)/31,0) | E13: =IFERROR(COUNTIF('Steps Tracker'!E277:E307,1)/31,0) | F13: =IFERROR(SUMIF('Running Tracker'!C277:C307,1,'Running Tracker'!D277:D307),0) | G13: =IFERROR(SUM('Expense & Savings'!E277:E307),0) | H13: =IFERROR(SUM('Expense & Savings'!F277:F307),0) | I13: =IFERROR(G13-H13,0) | J13: =IFERROR(I13/G13,0) | K13: =B13*0.25+C13*0.20+D13*0.15+E13*0.15+MIN(IFERROR(F13/'Goals & Settings'!B11,0),1)*0.10+MIN(IFERROR(I13/'Goals & Settings'!B12,0),1)*0.15
A14: November | B14: =IFERROR(AVERAGE('Salat Tracker'!I308:I337),0) | C14: =IFERROR(COUNTIFS('Gym Routine'!C308:C337,"Grind Day",'Gym Routine'!D308:D337,1)/21,0) | D14: =IFERROR(COUNTIF('Supplements'!E308:E337,1)/30,0) | E14: =IFERROR(COUNTIF('Steps Tracker'!E308:E337,1)/30,0) | F14: =IFERROR(SUMIF('Running Tracker'!C308:C337,1,'Running Tracker'!D308:D337),0) | G14: =IFERROR(SUM('Expense & Savings'!E308:E337),0) | H14: =IFERROR(SUM('Expense & Savings'!F308:F337),0) | I14: =IFERROR(G14-H14,0) | J14: =IFERROR(I14/G14,0) | K14: =B14*0.25+C14*0.20+D14*0.15+E14*0.15+MIN(IFERROR(F14/'Goals & Settings'!B11,0),1)*0.10+MIN(IFERROR(I14/'Goals & Settings'!B12,0),1)*0.15
A15: December | B15: =IFERROR(AVERAGE('Salat Tracker'!I338:I368),0) | C15: =IFERROR(COUNTIFS('Gym Routine'!C338:C368,"Grind Day",'Gym Routine'!D338:D368,1)/22,0) | D15: =IFERROR(COUNTIF('Supplements'!E338:E368,1)/31,0) | E15: =IFERROR(COUNTIF('Steps Tracker'!E338:E368,1)/31,0) | F15: =IFERROR(SUMIF('Running Tracker'!C338:C368,1,'Running Tracker'!D338:D368),0) | G15: =IFERROR(SUM('Expense & Savings'!E338:E368),0) | H15: =IFERROR(SUM('Expense & Savings'!F338:F368),0) | I15: =IFERROR(G15-H15,0) | J15: =IFERROR(I15/G15,0) | K15: =B15*0.25+C15*0.20+D15*0.15+E15*0.15+MIN(IFERROR(F15/'Goals & Settings'!B11,0),1)*0.10+MIN(IFERROR(I15/'Goals & Settings'!B12,0),1)*0.15
A16: YEAR 2026 TOTAL / AVG | B16: =AVERAGE(B4:B15) | C16: =AVERAGE(C4:C15) | D16: =AVERAGE(D4:D15) | E16: =AVERAGE(E4:E15) | F16: =SUM(F4:F15) | G16: =SUM(G4:G15) | H16: =SUM(H4:H15) | I16: =SUM(I4:I15) | J16: =IFERROR(I16/G16,0) | K16: =AVERAGE(K4:K15)
